<?xml version="1.0"?>
<robot name="tricycle_drive" xmlns:xacro="http://ros.org/wiki/xacro">
  <material name="Black">
    <color rgba="0 0 0 1" />
  </material>
  <material name="Grey">
    <color rgba="0.8 0.8 0.8 1" />
  </material>
  <material name="Orange">
    <color rgba="1 0.6 0 1" />
  </material>
  <material name="White">
    <color rgba="1 1 1 1" />
  </material>

  <link name="base_link" />

  <joint name="base_footprint_joint" type="fixed">
    <parent link="base_link"/>
    <child link="base_footprint"/>
    <origin xyz="0 0 0" rpy="0 0 0"/>
  </joint>

  <link name="base_footprint">
  </link>

  <!-- Chassis -->
  <link name="chassis">
    <collision>
      <!--<origin xyz="0.8 0 0.5" rpy="0 0 0" />-->
      <geometry>
        <box size="2 1 0.5" />
      </geometry>
    </collision>

    <visual>
      <!--<origin xyz="0.8 0 0.5" rpy="0 0 0" />-->
      <geometry>
        <box size="2 1 0.5" />
      </geometry>
      <material name="Orange" />
    </visual>

    <inertial>
      <!--<origin xyz="0.8 0 0.5" rpy="0 0 0" />-->
      <mass value="1" />
      <inertia ixx="0.126164" ixy="0.0" ixz="0.0" iyy="0.416519" iyz="0.0" izz="0.481014" />
    </inertial>
  </link>

  <joint name="chassis_joint" type="fixed">
    <origin xyz="0.8 0 0.5" rpy="0 0 0" />
    <parent link="base_link" />
    <child link="chassis" />
  </joint>


  <!-- left wheel Link -->
  <link name="left_wheel">
    <collision>
      <!--<origin xyz="-0.8 0.5 -0.2" rpy="-1.57 0 0" />-->
      <geometry>
        <cylinder length="0.08" radius="0.3" />
      </geometry>
    </collision>
    <visual>
      <!--<origin xyz="-0.8 0.5 -0.2" rpy="-1.57 0 0" />-->
      <geometry>
        <cylinder length="0.08" radius="0.3" />
      </geometry>
      <material name="Black" />
    </visual>

    <inertial>
      <!--<origin xyz="-0.8 0.5 -0.2" rpy="-1.57 0 0" />-->
      <mass value="2" />
      <inertia ixx="0.145833" ixy="0.0" ixz="0.0" iyy="0.145833" iyz="0.0" izz="0.125" />
    </inertial>
  </link>

  <joint name="left_wheel_joint" type="continuous">
    <origin xyz="-0.8 0.5 -0.2" rpy="-1.57 0 0" />
    <parent link="chassis" />
    <child link="left_wheel" />
    <axis xyz="0 0 1" />
    <dynamics damping="0.2" />
  </joint>

  <!-- right wheel Link -->
  <link name="right_wheel">
    <collision>
      <!--<origin xyz="-0.8 -0.5 -0.2" rpy="-1.57 0 0" />-->
      <geometry>
        <cylinder length="0.08" radius="0.3" />
      </geometry>
    </collision>
    <visual>
      <!--<origin xyz="-0.8 -0.5 -0.2" rpy="-1.57 0 0" />-->
      <geometry>
        <cylinder length="0.08" radius="0.3" />
      </geometry>
      <material name="Black" />
    </visual>

    <inertial>
      <!--<origin xyz="-0.8 -0.5 -0.2" rpy="-1.57 0 0" />-->
      <mass value="2" />
      <inertia ixx="0.145833" ixy="0.0" ixz="0.0" iyy="0.145833" iyz="0.0" izz="0.125" />
    </inertial>
  </link>

  <joint name="right_wheel_joint" type="continuous">
    <origin xyz="-0.8 -0.5 -0.2" rpy="-1.57 0 0" />
    <parent link="chassis" />
    <child link="right_wheel" />
    <axis xyz="0 0 1" />
    <dynamics damping="0.2" />
  </joint>

  <!-- Steering Link -->
  <link name="steering_link">
    <visual>
      <!--<origin xyz="0.9 0 -0.2" rpy="0 0 0" />-->
      <geometry>
        <box size="0.01 0.01 0.01" />
      </geometry>
      <material name="Black" />
    </visual>
    <inertial>
      <origin xyz="0 0 0" rpy="0 0 0" />
      <!--<origin xyz="0.9 0 -0.2" rpy="0 0 0" />-->
      <mass value="0.005" />
      <inertia ixx="0.1" ixy="0.0" ixz="0.0" iyy="0.1" iyz="0.0" izz="0.1" />
    </inertial>
  </link>

  <joint name="steering_joint" type="continuous">
    <origin xyz="0.9 0 -0.2" rpy="0 0 0" />
    <parent link="chassis" />
    <child link="steering_link" />
    <axis xyz="0 0 1" />
  </joint>

  <!-- traction wheel link -->
  <link name="wheel_front_link">
    <visual>
      <!--<origin xyz="0 0 0" rpy="-1.57 1.57 0" />-->
      <geometry>
        <cylinder length="0.08" radius="0.3" />
      </geometry>
      <material name="Black" />
    </visual>
    <inertial>
      <origin xyz="0 0 0" rpy="0 0 0" />
      <!--<origin xyz="0 0 0" rpy="-1.57 1.57 0" />-->
      <mass value="15" />
      <inertia ixx="1" ixy="0" ixz="0" iyy="1" iyz="0" izz="1" />
    </inertial>
    <collision>
      <!--<origin xyz="0 0 0" rpy="-1.57 1.57 0" />-->
      <geometry>
        <cylinder length="0.08" radius="0.3" />
      </geometry>
    </collision>
  </link>

  <joint name="traction_joint" type="continuous">
    <parent link="steering_link" />
    <child link="wheel_front_link" />
    <origin xyz="0 0 0" rpy="-1.57 1.57 0" />
    <axis xyz="0 0 1" />
  </joint>

  <ros2_control name="GazeboSystem" type="system">
    <hardware>
      <plugin>gazebo_ros2_control/GazeboSystem</plugin>
    </hardware>
    <joint name="steering_joint">
      <command_interface name="position" />
      <state_interface name="position" />
    </joint>
    <joint name="traction_joint">
      <command_interface name="velocity" />
      <state_interface name="velocity" />
      <state_interface name="position" />
    </joint>
  </ros2_control>

  <gazebo>
    <plugin filename="libgazebo_ros2_control.so" name="gazebo_ros2_control">
      <parameters>$(find misis_robot)/config/tricycle_drive_controller.yaml</parameters>
    </plugin>
  </gazebo>

  <joint name="laser_joint" type="fixed">
        <parent link="chassis"/>
        <child link="laser_frame"/>
        <origin xyz="0 0 0.27" rpy="0 0 0"/>
    </joint>

    <link name="laser_frame">
        <visual>
            <geometry>
                <cylinder radius="0.05" length="0.04"/>
            </geometry>
            <material name="red"/>
        </visual>
        <collision>
            <geometry>
                <cylinder radius="0.05" length="0.04"/>
            </geometry>
        </collision>
    </link>



    <gazebo reference="laser_frame">
        <material>Gazebo/Red</material>

        <sensor name="laser" type="ray">
            <pose> 0 0 0 0 0 0 </pose>
            <visualize>true</visualize>
            <update_rate>10</update_rate>
            <ray>
                <scan>
                    <horizontal>
                        <samples>360</samples>
                        <min_angle>-3.14</min_angle>
                        <max_angle>3.14</max_angle>
                    </horizontal>
                </scan>
                <range>
                    <min>0.3</min>
                    <max>12</max>
                </range>
            </ray>
            <plugin name="laser_controller" filename="libgazebo_ros_ray_sensor.so">
                <ros>
                    <argument>~/out:=scan</argument>
                </ros>
                <output_type>sensor_msgs/LaserScan</output_type>
                <frame_name>laser_frame</frame_name>
            </plugin>
        </sensor>
    </gazebo>

</robot>
